[31;1mcancelled[0m
Exception ignored in: <function StreamWriter.__del__ at 0x7fba56512ca0>
Traceback (most recent call last):
  File "/nix/store/qp5zys77biz7imbk6yy85q5pdv7qk84j-python3-3.11.6/lib/python3.11/asyncio/streams.py", line 395, in __del__
    self.close()
  File "/nix/store/qp5zys77biz7imbk6yy85q5pdv7qk84j-python3-3.11.6/lib/python3.11/asyncio/streams.py", line 343, in close
    return self._transport.close()
           ^^^^^^^^^^^^^^^^^^^^^^^
  File "/nix/store/qp5zys77biz7imbk6yy85q5pdv7qk84j-python3-3.11.6/lib/python3.11/asyncio/selector_events.py", line 860, in close
    self._loop.call_soon(self._call_connection_lost, None)
  File "/nix/store/qp5zys77biz7imbk6yy85q5pdv7qk84j-python3-3.11.6/lib/python3.11/asyncio/base_events.py", line 761, in call_soon
    self._check_closed()
  File "/nix/store/qp5zys77biz7imbk6yy85q5pdv7qk84j-python3-3.11.6/lib/python3.11/asyncio/base_events.py", line 519, in _check_closed
    raise RuntimeError('Event loop is closed')
RuntimeError: Event loop is closed
Exception ignored in: <function StreamWriter.__del__ at 0x7fba56512ca0>
Traceback (most recent call last):
  File "/nix/store/qp5zys77biz7imbk6yy85q5pdv7qk84j-python3-3.11.6/lib/python3.11/asyncio/streams.py", line 395, in __del__
    self.close()
  File "/nix/store/qp5zys77biz7imbk6yy85q5pdv7qk84j-python3-3.11.6/lib/python3.11/asyncio/streams.py", line 343, in close
    return self._transport.close()
           ^^^^^^^^^^^^^^^^^^^^^^^
  File "/nix/store/qp5zys77biz7imbk6yy85q5pdv7qk84j-python3-3.11.6/lib/python3.11/asyncio/selector_events.py", line 860, in close
    self._loop.call_soon(self._call_connection_lost, None)
  File "/nix/store/qp5zys77biz7imbk6yy85q5pdv7qk84j-python3-3.11.6/lib/python3.11/asyncio/base_events.py", line 761, in call_soon
    self._check_closed()
  File "/nix/store/qp5zys77biz7imbk6yy85q5pdv7qk84j-python3-3.11.6/lib/python3.11/asyncio/base_events.py", line 519, in _check_closed
    raise RuntimeError('Event loop is closed')
RuntimeError: Event loop is closed
